----------- 18/04/2025 15:42:09,08 ------------- 
From https://github.com/EduardoDosSantosFerreira/cleancrow
 * branch            main       -> FETCH_HEAD
Already up to date.
[main f671cf4] Atualiza칞칚o autom치tica: 2025-04-18 15:42:11
 2 files changed, 6 insertions(+), 2 deletions(-)
 create mode 100644 python/log_autocommit.txt
git: 'credential-manager-core' is not a git command. See 'git --help'.
To https://github.com/EduardoDosSantosFerreira/cleancrow
   d0a3a54..f671cf4  main -> main
Criando commit...
Commit realizado com sucesso: Atualiza巫o autom磬ica: 2025-04-18 15:42:11
---------------------------------------- 
----------- 18/04/2025 15:42:43,42 ------------- 
From https://github.com/EduardoDosSantosFerreira/cleancrow
 * branch            main       -> FETCH_HEAD
Already up to date.
warning: in the working copy of 'python/log_autocommit.txt', LF will be replaced by CRLF the next time Git touches it
[main 17c8d59] Atualiza칞칚o autom치tica: 2025-04-18 15:42:44
 1 file changed, 13 insertions(+)
git: 'credential-manager-core' is not a git command. See 'git --help'.
To https://github.com/EduardoDosSantosFerreira/cleancrow
   f671cf4..17c8d59  main -> main
Criando commit...
Commit realizado com sucesso: Atualiza巫o autom磬ica: 2025-04-18 15:42:44
---------------------------------------- 
----------- 18/04/2025 15:54:16,49 ------------- 
From https://github.com/EduardoDosSantosFerreira/cleancrow
 * branch            main       -> FETCH_HEAD
Already up to date.
warning: in the working copy of 'python/log_autocommit.txt', LF will be replaced by CRLF the next time Git touches it
[main b139775] Atualiza칞칚o autom치tica: 2025-04-18 15:54:17
 1 file changed, 13 insertions(+)
git: 'credential-manager-core' is not a git command. See 'git --help'.
To https://github.com/EduardoDosSantosFerreira/cleancrow
   17c8d59..b139775  main -> main
Criando commit...
Commit realizado com sucesso: Atualiza巫o autom磬ica: 2025-04-18 15:54:17
---------------------------------------- 
----------- 18/04/2025 17:00:00,90 ------------- 
From https://github.com/EduardoDosSantosFerreira/cleancrow
 * branch            main       -> FETCH_HEAD
Already up to date.
warning: in the working copy of 'python/log_autocommit.txt', LF will be replaced by CRLF the next time Git touches it
[main c1248cf] Atualiza칞칚o autom치tica: 2025-04-18 17:00:02
 1 file changed, 13 insertions(+)
git: 'credential-manager-core' is not a git command. See 'git --help'.
To https://github.com/EduardoDosSantosFerreira/cleancrow
   b139775..c1248cf  main -> main
Criando commit...
Commit realizado com sucesso: Atualiza巫o autom磬ica: 2025-04-18 17:00:02
---------------------------------------- 
----------- 19/04/2025 14:30:01,74 ------------- 
From https://github.com/EduardoDosSantosFerreira/cleancrow
 * branch            main       -> FETCH_HEAD
Already up to date.
warning: in the working copy of 'python/log_autocommit.txt', LF will be replaced by CRLF the next time Git touches it
[main 6b709be] Atualiza칞칚o autom치tica: 2025-04-19 14:30:03
 1 file changed, 13 insertions(+)
fatal: Unable to persist credentials with the 'wincredman' credential store.
See https://aka.ms/gcm/credstores for more information.
git: 'credential-manager-core' is not a git command. See 'git --help'.
bash: line 1: /dev/tty: No such device or address
error: failed to execute prompt script (exit code 1)
fatal: could not read Username for 'https://github.com': No such file or directory
Criando commit...
Traceback (most recent call last):
  File "C:\Users\Eduardo\Documents\cleancrow\python\auto_commit.py", line 37, in <module>
    auto_commit()
    ~~~~~~~~~~~^^
  File "C:\Users\Eduardo\Documents\cleancrow\python\auto_commit.py", line 26, in auto_commit
    subprocess.run(['git', 'push', 'origin', 'main'], check=True)
    ~~~~~~~~~~~~~~^^^^^^^^^^^^^^^^^^^^^^^^^^^^^^^^^^^^^^^^^^^^^^^
  File "C:\Users\Eduardo\AppData\Local\Programs\Python\Python313\Lib\subprocess.py", line 577, in run
    raise CalledProcessError(retcode, process.args,
                             output=stdout, stderr=stderr)
subprocess.CalledProcessError: Command '['git', 'push', 'origin', 'main']' returned non-zero exit status 128.
---------------------------------------- 
----------- 19/04/2025 17:00:01,34 ------------- 
From https://github.com/EduardoDosSantosFerreira/cleancrow
 * branch            main       -> FETCH_HEAD
Already up to date.
warning: in the working copy of 'python/log_autocommit.txt', LF will be replaced by CRLF the next time Git touches it
[main 3d85c92] Atualiza칞칚o autom치tica: 2025-04-19 17:00:03
 1 file changed, 26 insertions(+)
fatal: Unable to persist credentials with the 'wincredman' credential store.
See https://aka.ms/gcm/credstores for more information.
git: 'credential-manager-core' is not a git command. See 'git --help'.
bash: line 1: /dev/tty: No such device or address
error: failed to execute prompt script (exit code 1)
fatal: could not read Username for 'https://github.com': No such file or directory
Criando commit...
Traceback (most recent call last):
  File "C:\Users\Eduardo\Documents\cleancrow\python\auto_commit.py", line 37, in <module>
    auto_commit()
    ~~~~~~~~~~~^^
  File "C:\Users\Eduardo\Documents\cleancrow\python\auto_commit.py", line 26, in auto_commit
    subprocess.run(['git', 'push', 'origin', 'main'], check=True)
    ~~~~~~~~~~~~~~^^^^^^^^^^^^^^^^^^^^^^^^^^^^^^^^^^^^^^^^^^^^^^^
  File "C:\Users\Eduardo\AppData\Local\Programs\Python\Python313\Lib\subprocess.py", line 577, in run
    raise CalledProcessError(retcode, process.args,
                             output=stdout, stderr=stderr)
subprocess.CalledProcessError: Command '['git', 'push', 'origin', 'main']' returned non-zero exit status 128.
---------------------------------------- 
----------- 19/04/2025 19:30:01,56 ------------- 
From https://github.com/EduardoDosSantosFerreira/cleancrow
 * branch            main       -> FETCH_HEAD
Already up to date.
warning: in the working copy of 'python/log_autocommit.txt', LF will be replaced by CRLF the next time Git touches it
[main a771a3d] Atualiza칞칚o autom치tica: 2025-04-19 19:30:03
 1 file changed, 26 insertions(+)
fatal: Unable to persist credentials with the 'wincredman' credential store.
See https://aka.ms/gcm/credstores for more information.
git: 'credential-manager-core' is not a git command. See 'git --help'.
bash: line 1: /dev/tty: No such device or address
error: failed to execute prompt script (exit code 1)
fatal: could not read Username for 'https://github.com': No such file or directory
Criando commit...
Traceback (most recent call last):
  File "C:\Users\Eduardo\Documents\cleancrow\python\auto_commit.py", line 37, in <module>
    auto_commit()
    ~~~~~~~~~~~^^
  File "C:\Users\Eduardo\Documents\cleancrow\python\auto_commit.py", line 26, in auto_commit
    subprocess.run(['git', 'push', 'origin', 'main'], check=True)
    ~~~~~~~~~~~~~~^^^^^^^^^^^^^^^^^^^^^^^^^^^^^^^^^^^^^^^^^^^^^^^
  File "C:\Users\Eduardo\AppData\Local\Programs\Python\Python313\Lib\subprocess.py", line 577, in run
    raise CalledProcessError(retcode, process.args,
                             output=stdout, stderr=stderr)
subprocess.CalledProcessError: Command '['git', 'push', 'origin', 'main']' returned non-zero exit status 128.
---------------------------------------- 
----------- 20/04/2025 14:30:01,96 ------------- 
From https://github.com/EduardoDosSantosFerreira/cleancrow
 * branch            main       -> FETCH_HEAD
Already up to date.
warning: in the working copy of 'python/log_autocommit.txt', LF will be replaced by CRLF the next time Git touches it
[main 1ceda4e] Atualiza칞칚o autom치tica: 2025-04-20 14:30:05
 1 file changed, 26 insertions(+)
fatal: Unable to persist credentials with the 'wincredman' credential store.
See https://aka.ms/gcm/credstores for more information.
git: 'credential-manager-core' is not a git command. See 'git --help'.
bash: line 1: /dev/tty: No such device or address
error: failed to execute prompt script (exit code 1)
fatal: could not read Username for 'https://github.com': No such file or directory
Criando commit...
Traceback (most recent call last):
  File "C:\Users\Eduardo\Documents\cleancrow\python\auto_commit.py", line 37, in <module>
    auto_commit()
    ~~~~~~~~~~~^^
  File "C:\Users\Eduardo\Documents\cleancrow\python\auto_commit.py", line 26, in auto_commit
    subprocess.run(['git', 'push', 'origin', 'main'], check=True)
    ~~~~~~~~~~~~~~^^^^^^^^^^^^^^^^^^^^^^^^^^^^^^^^^^^^^^^^^^^^^^^
  File "C:\Users\Eduardo\AppData\Local\Programs\Python\Python313\Lib\subprocess.py", line 577, in run
    raise CalledProcessError(retcode, process.args,
                             output=stdout, stderr=stderr)
subprocess.CalledProcessError: Command '['git', 'push', 'origin', 'main']' returned non-zero exit status 128.
---------------------------------------- 
----------- 20/04/2025 17:00:01,54 ------------- 
From https://github.com/EduardoDosSantosFerreira/cleancrow
 * branch            main       -> FETCH_HEAD
Already up to date.
warning: in the working copy of 'python/log_autocommit.txt', LF will be replaced by CRLF the next time Git touches it
[main 28d4910] Atualiza칞칚o autom치tica: 2025-04-20 17:00:04
 1 file changed, 26 insertions(+)
fatal: Unable to persist credentials with the 'wincredman' credential store.
See https://aka.ms/gcm/credstores for more information.
git: 'credential-manager-core' is not a git command. See 'git --help'.
bash: line 1: /dev/tty: No such device or address
error: failed to execute prompt script (exit code 1)
fatal: could not read Username for 'https://github.com': No such file or directory
Criando commit...
Traceback (most recent call last):
  File "C:\Users\Eduardo\Documents\cleancrow\python\auto_commit.py", line 37, in <module>
    auto_commit()
    ~~~~~~~~~~~^^
  File "C:\Users\Eduardo\Documents\cleancrow\python\auto_commit.py", line 26, in auto_commit
    subprocess.run(['git', 'push', 'origin', 'main'], check=True)
    ~~~~~~~~~~~~~~^^^^^^^^^^^^^^^^^^^^^^^^^^^^^^^^^^^^^^^^^^^^^^^
  File "C:\Users\Eduardo\AppData\Local\Programs\Python\Python313\Lib\subprocess.py", line 577, in run
    raise CalledProcessError(retcode, process.args,
                             output=stdout, stderr=stderr)
subprocess.CalledProcessError: Command '['git', 'push', 'origin', 'main']' returned non-zero exit status 128.
---------------------------------------- 
----------- 20/04/2025 19:30:01,76 ------------- 
From https://github.com/EduardoDosSantosFerreira/cleancrow
 * branch            main       -> FETCH_HEAD
Already up to date.
warning: in the working copy of 'python/log_autocommit.txt', LF will be replaced by CRLF the next time Git touches it
[main c77afd5] Atualiza칞칚o autom치tica: 2025-04-20 19:30:03
 1 file changed, 26 insertions(+)
fatal: Unable to persist credentials with the 'wincredman' credential store.
See https://aka.ms/gcm/credstores for more information.
git: 'credential-manager-core' is not a git command. See 'git --help'.
bash: line 1: /dev/tty: No such device or address
error: failed to execute prompt script (exit code 1)
fatal: could not read Username for 'https://github.com': No such file or directory
Criando commit...
Traceback (most recent call last):
  File "C:\Users\Eduardo\Documents\cleancrow\python\auto_commit.py", line 37, in <module>
    auto_commit()
    ~~~~~~~~~~~^^
  File "C:\Users\Eduardo\Documents\cleancrow\python\auto_commit.py", line 26, in auto_commit
    subprocess.run(['git', 'push', 'origin', 'main'], check=True)
    ~~~~~~~~~~~~~~^^^^^^^^^^^^^^^^^^^^^^^^^^^^^^^^^^^^^^^^^^^^^^^
  File "C:\Users\Eduardo\AppData\Local\Programs\Python\Python313\Lib\subprocess.py", line 577, in run
    raise CalledProcessError(retcode, process.args,
                             output=stdout, stderr=stderr)
subprocess.CalledProcessError: Command '['git', 'push', 'origin', 'main']' returned non-zero exit status 128.
---------------------------------------- 
----------- 20/04/2025 22:00:02,57 ------------- 
From https://github.com/EduardoDosSantosFerreira/cleancrow
 * branch            main       -> FETCH_HEAD
Already up to date.
warning: in the working copy of 'python/log_autocommit.txt', LF will be replaced by CRLF the next time Git touches it
[main ea1f014] Atualiza칞칚o autom치tica: 2025-04-20 22:00:07
 1 file changed, 26 insertions(+)
fatal: Unable to persist credentials with the 'wincredman' credential store.
See https://aka.ms/gcm/credstores for more information.
git: 'credential-manager-core' is not a git command. See 'git --help'.
bash: line 1: /dev/tty: No such device or address
error: failed to execute prompt script (exit code 1)
fatal: could not read Username for 'https://github.com': No such file or directory
Criando commit...
Traceback (most recent call last):
  File "C:\Users\Eduardo\Documents\cleancrow\python\auto_commit.py", line 37, in <module>
    auto_commit()
    ~~~~~~~~~~~^^
  File "C:\Users\Eduardo\Documents\cleancrow\python\auto_commit.py", line 26, in auto_commit
    subprocess.run(['git', 'push', 'origin', 'main'], check=True)
    ~~~~~~~~~~~~~~^^^^^^^^^^^^^^^^^^^^^^^^^^^^^^^^^^^^^^^^^^^^^^^
  File "C:\Users\Eduardo\AppData\Local\Programs\Python\Python313\Lib\subprocess.py", line 577, in run
    raise CalledProcessError(retcode, process.args,
                             output=stdout, stderr=stderr)
subprocess.CalledProcessError: Command '['git', 'push', 'origin', 'main']' returned non-zero exit status 128.
---------------------------------------- 
----------- 21/04/2025 17:00:02,13 ------------- 
From https://github.com/EduardoDosSantosFerreira/cleancrow
 * branch            main       -> FETCH_HEAD
Already up to date.
warning: in the working copy of 'python/log_autocommit.txt', LF will be replaced by CRLF the next time Git touches it
[main ea60b57] Atualiza칞칚o autom치tica: 2025-04-21 17:00:05
 1 file changed, 26 insertions(+)
fatal: Unable to persist credentials with the 'wincredman' credential store.
See https://aka.ms/gcm/credstores for more information.
git: 'credential-manager-core' is not a git command. See 'git --help'.
bash: line 1: /dev/tty: No such device or address
error: failed to execute prompt script (exit code 1)
fatal: could not read Username for 'https://github.com': No such file or directory
Criando commit...
Traceback (most recent call last):
  File "C:\Users\Eduardo\Documents\cleancrow\python\auto_commit.py", line 37, in <module>
    auto_commit()
    ~~~~~~~~~~~^^
  File "C:\Users\Eduardo\Documents\cleancrow\python\auto_commit.py", line 26, in auto_commit
    subprocess.run(['git', 'push', 'origin', 'main'], check=True)
    ~~~~~~~~~~~~~~^^^^^^^^^^^^^^^^^^^^^^^^^^^^^^^^^^^^^^^^^^^^^^^
  File "C:\Users\Eduardo\AppData\Local\Programs\Python\Python313\Lib\subprocess.py", line 577, in run
    raise CalledProcessError(retcode, process.args,
                             output=stdout, stderr=stderr)
subprocess.CalledProcessError: Command '['git', 'push', 'origin', 'main']' returned non-zero exit status 128.
---------------------------------------- 
----------- 21/04/2025 19:30:02,07 ------------- 
From https://github.com/EduardoDosSantosFerreira/cleancrow
 * branch            main       -> FETCH_HEAD
Already up to date.
warning: in the working copy of 'python/log_autocommit.txt', LF will be replaced by CRLF the next time Git touches it
[main a112500] Atualiza칞칚o autom치tica: 2025-04-21 19:30:04
 1 file changed, 26 insertions(+)
fatal: Unable to persist credentials with the 'wincredman' credential store.
See https://aka.ms/gcm/credstores for more information.
git: 'credential-manager-core' is not a git command. See 'git --help'.
bash: line 1: /dev/tty: No such device or address
error: failed to execute prompt script (exit code 1)
fatal: could not read Username for 'https://github.com': No such file or directory
Criando commit...
Traceback (most recent call last):
  File "C:\Users\Eduardo\Documents\cleancrow\python\auto_commit.py", line 37, in <module>
    auto_commit()
    ~~~~~~~~~~~^^
  File "C:\Users\Eduardo\Documents\cleancrow\python\auto_commit.py", line 26, in auto_commit
    subprocess.run(['git', 'push', 'origin', 'main'], check=True)
    ~~~~~~~~~~~~~~^^^^^^^^^^^^^^^^^^^^^^^^^^^^^^^^^^^^^^^^^^^^^^^
  File "C:\Users\Eduardo\AppData\Local\Programs\Python\Python313\Lib\subprocess.py", line 577, in run
    raise CalledProcessError(retcode, process.args,
                             output=stdout, stderr=stderr)
subprocess.CalledProcessError: Command '['git', 'push', 'origin', 'main']' returned non-zero exit status 128.
---------------------------------------- 
----------- 21/04/2025 22:00:02,02 ------------- 
From https://github.com/EduardoDosSantosFerreira/cleancrow
 * branch            main       -> FETCH_HEAD
Already up to date.
warning: in the working copy of 'python/log_autocommit.txt', LF will be replaced by CRLF the next time Git touches it
[main 34e43a7] Atualiza칞칚o autom치tica: 2025-04-21 22:00:03
 1 file changed, 26 insertions(+)
git: 'credential-manager-core' is not a git command. See 'git --help'.
To https://github.com/EduardoDosSantosFerreira/cleancrow
   c1248cf..34e43a7  main -> main
Criando commit...
Commit realizado com sucesso: Atualiza巫o autom磬ica: 2025-04-21 22:00:03
---------------------------------------- 
----------- 22/04/2025 19:30:01,97 ------------- 
From https://github.com/EduardoDosSantosFerreira/cleancrow
 * branch            main       -> FETCH_HEAD
Already up to date.
warning: in the working copy of 'python/log_autocommit.txt', LF will be replaced by CRLF the next time Git touches it
[main ef9fbf3] Atualiza칞칚o autom치tica: 2025-04-22 19:30:06
 1 file changed, 13 insertions(+)
fatal: Unable to persist credentials with the 'wincredman' credential store.
See https://aka.ms/gcm/credstores for more information.
git: 'credential-manager-core' is not a git command. See 'git --help'.
bash: line 1: /dev/tty: No such device or address
error: failed to execute prompt script (exit code 1)
fatal: could not read Username for 'https://github.com': No such file or directory
Criando commit...
Traceback (most recent call last):
  File "C:\Users\Eduardo\Documents\cleancrow\python\auto_commit.py", line 37, in <module>
    auto_commit()
    ~~~~~~~~~~~^^
  File "C:\Users\Eduardo\Documents\cleancrow\python\auto_commit.py", line 26, in auto_commit
    subprocess.run(['git', 'push', 'origin', 'main'], check=True)
    ~~~~~~~~~~~~~~^^^^^^^^^^^^^^^^^^^^^^^^^^^^^^^^^^^^^^^^^^^^^^^
  File "C:\Users\Eduardo\AppData\Local\Programs\Python\Python313\Lib\subprocess.py", line 577, in run
    raise CalledProcessError(retcode, process.args,
                             output=stdout, stderr=stderr)
subprocess.CalledProcessError: Command '['git', 'push', 'origin', 'main']' returned non-zero exit status 128.
---------------------------------------- 
----------- 22/04/2025 22:00:02,34 ------------- 
From https://github.com/EduardoDosSantosFerreira/cleancrow
 * branch            main       -> FETCH_HEAD
Already up to date.
warning: in the working copy of 'python/log_autocommit.txt', LF will be replaced by CRLF the next time Git touches it
[main 71f03fe] Atualiza칞칚o autom치tica: 2025-04-22 22:00:05
 1 file changed, 26 insertions(+)
fatal: Unable to persist credentials with the 'wincredman' credential store.
See https://aka.ms/gcm/credstores for more information.
git: 'credential-manager-core' is not a git command. See 'git --help'.
bash: line 1: /dev/tty: No such device or address
error: failed to execute prompt script (exit code 1)
fatal: could not read Username for 'https://github.com': No such file or directory
Criando commit...
Traceback (most recent call last):
  File "C:\Users\Eduardo\Documents\cleancrow\python\auto_commit.py", line 37, in <module>
    auto_commit()
    ~~~~~~~~~~~^^
  File "C:\Users\Eduardo\Documents\cleancrow\python\auto_commit.py", line 26, in auto_commit
    subprocess.run(['git', 'push', 'origin', 'main'], check=True)
    ~~~~~~~~~~~~~~^^^^^^^^^^^^^^^^^^^^^^^^^^^^^^^^^^^^^^^^^^^^^^^
  File "C:\Users\Eduardo\AppData\Local\Programs\Python\Python313\Lib\subprocess.py", line 577, in run
    raise CalledProcessError(retcode, process.args,
                             output=stdout, stderr=stderr)
subprocess.CalledProcessError: Command '['git', 'push', 'origin', 'main']' returned non-zero exit status 128.
---------------------------------------- 
----------- 23/04/2025 12:00:01,86 ------------- 
