----------- 25/04/2025 19:32:37,33 ------------- 
From https://github.com/EduardoDosSantosFerreira/cleancrow
 * branch            main       -> FETCH_HEAD
Already up to date.
[main 3531beb] Atualiza칞칚o autom치tica: 2025-04-25 19:32:39
 1 file changed, 1 insertion(+), 575 deletions(-)
git: 'credential-manager-core' is not a git command. See 'git --help'.
To https://github.com/EduardoDosSantosFerreira/cleancrow
   d6885a2..3531beb  main -> main
Criando commit...
Commit realizado com sucesso: Atualiza巫o autom磬ica: 2025-04-25 19:32:39
---------------------------------------- 
----------- 25/04/2025 22:00:02,38 ------------- 
Criando commit...
Traceback (most recent call last):
  File "C:\Users\Eduardo\Documents\cleancrow\python\auto_commit.py", line 37, in <module>
    auto_commit()
    ~~~~~~~~~~~^^
  File "C:\Users\Eduardo\Documents\cleancrow\python\auto_commit.py", line 16, in auto_commit
    subprocess.run(['git', 'pull', 'origin', 'main'], check=True)
    ~~~~~~~~~~~~~~^^^^^^^^^^^^^^^^^^^^^^^^^^^^^^^^^^^^^^^^^^^^^^^
  File "C:\Users\Eduardo\AppData\Local\Programs\Python\Python313\Lib\subprocess.py", line 577, in run
    raise CalledProcessError(retcode, process.args,
                             output=stdout, stderr=stderr)
subprocess.CalledProcessError: Command '['git', 'pull', 'origin', 'main']' returned non-zero exit status 1.
---------------------------------------- 
----------- 26/04/2025 22:00:01,89 ------------- 
From https://github.com/EduardoDosSantosFerreira/cleancrow
 * branch            main       -> FETCH_HEAD
Already up to date.
warning: in the working copy of 'python/log_autocommit.txt', LF will be replaced by CRLF the next time Git touches it
[main 4300a62] Atualiza칞칚o autom치tica: 2025-04-26 22:00:04
 1 file changed, 26 insertions(+)
git: 'credential-manager-core' is not a git command. See 'git --help'.
To https://github.com/EduardoDosSantosFerreira/cleancrow
   3531beb..4300a62  main -> main
Criando commit...
Commit realizado com sucesso: Atualiza巫o autom磬ica: 2025-04-26 22:00:04
---------------------------------------- 
----------- 27/04/2025 17:00:01,87 ------------- 
From https://github.com/EduardoDosSantosFerreira/cleancrow
 * branch            main       -> FETCH_HEAD
Already up to date.
warning: in the working copy of 'python/log_autocommit.txt', LF will be replaced by CRLF the next time Git touches it
[main 00553bd] Atualiza칞칚o autom치tica: 2025-04-27 17:00:05
 1 file changed, 13 insertions(+)
git: 'credential-manager-core' is not a git command. See 'git --help'.
To https://github.com/EduardoDosSantosFerreira/cleancrow
   4300a62..00553bd  main -> main
Criando commit...
Commit realizado com sucesso: Atualiza巫o autom磬ica: 2025-04-27 17:00:05
---------------------------------------- 
----------- 27/04/2025 19:30:01,74 ------------- 
From https://github.com/EduardoDosSantosFerreira/cleancrow
 * branch            main       -> FETCH_HEAD
Already up to date.
warning: in the working copy of 'python/log_autocommit.txt', LF will be replaced by CRLF the next time Git touches it
[main a792a87] Atualiza칞칚o autom치tica: 2025-04-27 19:30:04
 1 file changed, 13 insertions(+)
git: 'credential-manager-core' is not a git command. See 'git --help'.
To https://github.com/EduardoDosSantosFerreira/cleancrow
   00553bd..a792a87  main -> main
Criando commit...
Commit realizado com sucesso: Atualiza巫o autom磬ica: 2025-04-27 19:30:04
---------------------------------------- 
----------- 27/04/2025 22:00:02,02 ------------- 
From https://github.com/EduardoDosSantosFerreira/cleancrow
 * branch            main       -> FETCH_HEAD
Already up to date.
warning: in the working copy of 'python/log_autocommit.txt', LF will be replaced by CRLF the next time Git touches it
[main 1418a29] Atualiza칞칚o autom치tica: 2025-04-27 22:00:04
 1 file changed, 13 insertions(+)
git: 'credential-manager-core' is not a git command. See 'git --help'.
To https://github.com/EduardoDosSantosFerreira/cleancrow
   a792a87..1418a29  main -> main
Criando commit...
Commit realizado com sucesso: Atualiza巫o autom磬ica: 2025-04-27 22:00:04
---------------------------------------- 
----------- 28/04/2025  7:00:01,39 ------------- 
From https://github.com/EduardoDosSantosFerreira/cleancrow
 * branch            main       -> FETCH_HEAD
Already up to date.
warning: in the working copy of 'python/log_autocommit.txt', LF will be replaced by CRLF the next time Git touches it
[main 515fa2f] Atualiza칞칚o autom치tica: 2025-04-28 07:00:03
 1 file changed, 13 insertions(+)
fatal: Unable to persist credentials with the 'wincredman' credential store.
See https://aka.ms/gcm/credstores for more information.
git: 'credential-manager-core' is not a git command. See 'git --help'.
bash: line 1: /dev/tty: No such device or address
error: failed to execute prompt script (exit code 1)
fatal: could not read Username for 'https://github.com': No such file or directory
Criando commit...
Traceback (most recent call last):
  File "C:\Users\Eduardo\Documents\cleancrow\python\auto_commit.py", line 37, in <module>
    auto_commit()
    ~~~~~~~~~~~^^
  File "C:\Users\Eduardo\Documents\cleancrow\python\auto_commit.py", line 26, in auto_commit
    subprocess.run(['git', 'push', 'origin', 'main'], check=True)
    ~~~~~~~~~~~~~~^^^^^^^^^^^^^^^^^^^^^^^^^^^^^^^^^^^^^^^^^^^^^^^
  File "C:\Users\Eduardo\AppData\Local\Programs\Python\Python313\Lib\subprocess.py", line 577, in run
    raise CalledProcessError(retcode, process.args,
                             output=stdout, stderr=stderr)
subprocess.CalledProcessError: Command '['git', 'push', 'origin', 'main']' returned non-zero exit status 128.
---------------------------------------- 
----------- 28/04/2025  9:12:19,11 ------------- 
From https://github.com/EduardoDosSantosFerreira/cleancrow
 * branch            main       -> FETCH_HEAD
Already up to date.
warning: in the working copy of 'python/log_autocommit.txt', LF will be replaced by CRLF the next time Git touches it
[main d8e02af] Atualiza칞칚o autom치tica: 2025-04-28 09:12:26
 1 file changed, 26 insertions(+)
git: 'credential-manager-core' is not a git command. See 'git --help'.
To https://github.com/EduardoDosSantosFerreira/cleancrow
   1418a29..d8e02af  main -> main
Criando commit...
Commit realizado com sucesso: Atualiza巫o autom磬ica: 2025-04-28 09:12:26
---------------------------------------- 
----------- 28/04/2025  9:30:01,19 ------------- 
From https://github.com/EduardoDosSantosFerreira/cleancrow
 * branch            main       -> FETCH_HEAD
Already up to date.
warning: in the working copy of 'python/log_autocommit.txt', LF will be replaced by CRLF the next time Git touches it
[main 6d8f4a4] Atualiza칞칚o autom치tica: 2025-04-28 09:30:02
 1 file changed, 13 insertions(+)
fatal: Unable to persist credentials with the 'wincredman' credential store.
See https://aka.ms/gcm/credstores for more information.
git: 'credential-manager-core' is not a git command. See 'git --help'.
bash: line 1: /dev/tty: No such device or address
error: failed to execute prompt script (exit code 1)
fatal: could not read Username for 'https://github.com': No such file or directory
Criando commit...
Traceback (most recent call last):
  File "C:\Users\Eduardo\Documents\cleancrow\python\auto_commit.py", line 37, in <module>
    auto_commit()
    ~~~~~~~~~~~^^
  File "C:\Users\Eduardo\Documents\cleancrow\python\auto_commit.py", line 26, in auto_commit
    subprocess.run(['git', 'push', 'origin', 'main'], check=True)
    ~~~~~~~~~~~~~~^^^^^^^^^^^^^^^^^^^^^^^^^^^^^^^^^^^^^^^^^^^^^^^
  File "C:\Users\Eduardo\AppData\Local\Programs\Python\Python313\Lib\subprocess.py", line 577, in run
    raise CalledProcessError(retcode, process.args,
                             output=stdout, stderr=stderr)
subprocess.CalledProcessError: Command '['git', 'push', 'origin', 'main']' returned non-zero exit status 128.
---------------------------------------- 
----------- 28/04/2025 12:00:01,36 ------------- 
From https://github.com/EduardoDosSantosFerreira/cleancrow
 * branch            main       -> FETCH_HEAD
Already up to date.
warning: in the working copy of 'python/log_autocommit.txt', LF will be replaced by CRLF the next time Git touches it
[main 2ff431a] Atualiza칞칚o autom치tica: 2025-04-28 12:00:02
 1 file changed, 26 insertions(+)
fatal: Unable to persist credentials with the 'wincredman' credential store.
See https://aka.ms/gcm/credstores for more information.
git: 'credential-manager-core' is not a git command. See 'git --help'.
bash: line 1: /dev/tty: No such device or address
error: failed to execute prompt script (exit code 1)
fatal: could not read Username for 'https://github.com': No such file or directory
Criando commit...
Traceback (most recent call last):
  File "C:\Users\Eduardo\Documents\cleancrow\python\auto_commit.py", line 37, in <module>
    auto_commit()
    ~~~~~~~~~~~^^
  File "C:\Users\Eduardo\Documents\cleancrow\python\auto_commit.py", line 26, in auto_commit
    subprocess.run(['git', 'push', 'origin', 'main'], check=True)
    ~~~~~~~~~~~~~~^^^^^^^^^^^^^^^^^^^^^^^^^^^^^^^^^^^^^^^^^^^^^^^
  File "C:\Users\Eduardo\AppData\Local\Programs\Python\Python313\Lib\subprocess.py", line 577, in run
    raise CalledProcessError(retcode, process.args,
                             output=stdout, stderr=stderr)
subprocess.CalledProcessError: Command '['git', 'push', 'origin', 'main']' returned non-zero exit status 128.
---------------------------------------- 
----------- 28/04/2025 14:30:01,46 ------------- 
From https://github.com/EduardoDosSantosFerreira/cleancrow
 * branch            main       -> FETCH_HEAD
Already up to date.
warning: in the working copy of 'python/log_autocommit.txt', LF will be replaced by CRLF the next time Git touches it
[main 0f069a7] Atualiza칞칚o autom치tica: 2025-04-28 14:30:03
 1 file changed, 26 insertions(+)
fatal: Unable to persist credentials with the 'wincredman' credential store.
See https://aka.ms/gcm/credstores for more information.
git: 'credential-manager-core' is not a git command. See 'git --help'.
bash: line 1: /dev/tty: No such device or address
error: failed to execute prompt script (exit code 1)
fatal: could not read Username for 'https://github.com': No such file or directory
Criando commit...
Traceback (most recent call last):
  File "C:\Users\Eduardo\Documents\cleancrow\python\auto_commit.py", line 37, in <module>
    auto_commit()
    ~~~~~~~~~~~^^
  File "C:\Users\Eduardo\Documents\cleancrow\python\auto_commit.py", line 26, in auto_commit
    subprocess.run(['git', 'push', 'origin', 'main'], check=True)
    ~~~~~~~~~~~~~~^^^^^^^^^^^^^^^^^^^^^^^^^^^^^^^^^^^^^^^^^^^^^^^
  File "C:\Users\Eduardo\AppData\Local\Programs\Python\Python313\Lib\subprocess.py", line 577, in run
    raise CalledProcessError(retcode, process.args,
                             output=stdout, stderr=stderr)
subprocess.CalledProcessError: Command '['git', 'push', 'origin', 'main']' returned non-zero exit status 128.
---------------------------------------- 
----------- 28/04/2025 17:00:01,56 ------------- 
From https://github.com/EduardoDosSantosFerreira/cleancrow
 * branch            main       -> FETCH_HEAD
Already up to date.
warning: in the working copy of 'python/log_autocommit.txt', LF will be replaced by CRLF the next time Git touches it
[main 3197e02] Atualiza칞칚o autom치tica: 2025-04-28 17:00:02
 1 file changed, 26 insertions(+)
fatal: Unable to persist credentials with the 'wincredman' credential store.
See https://aka.ms/gcm/credstores for more information.
git: 'credential-manager-core' is not a git command. See 'git --help'.
bash: line 1: /dev/tty: No such device or address
error: failed to execute prompt script (exit code 1)
fatal: could not read Username for 'https://github.com': No such file or directory
Criando commit...
Traceback (most recent call last):
  File "C:\Users\Eduardo\Documents\cleancrow\python\auto_commit.py", line 37, in <module>
    auto_commit()
    ~~~~~~~~~~~^^
  File "C:\Users\Eduardo\Documents\cleancrow\python\auto_commit.py", line 26, in auto_commit
    subprocess.run(['git', 'push', 'origin', 'main'], check=True)
    ~~~~~~~~~~~~~~^^^^^^^^^^^^^^^^^^^^^^^^^^^^^^^^^^^^^^^^^^^^^^^
  File "C:\Users\Eduardo\AppData\Local\Programs\Python\Python313\Lib\subprocess.py", line 577, in run
    raise CalledProcessError(retcode, process.args,
                             output=stdout, stderr=stderr)
subprocess.CalledProcessError: Command '['git', 'push', 'origin', 'main']' returned non-zero exit status 128.
---------------------------------------- 
----------- 28/04/2025 19:30:01,35 ------------- 
From https://github.com/EduardoDosSantosFerreira/cleancrow
 * branch            main       -> FETCH_HEAD
Already up to date.
warning: in the working copy of 'python/log_autocommit.txt', LF will be replaced by CRLF the next time Git touches it
[main a6f7d1d] Atualiza칞칚o autom치tica: 2025-04-28 19:30:03
 1 file changed, 26 insertions(+)
fatal: Unable to persist credentials with the 'wincredman' credential store.
See https://aka.ms/gcm/credstores for more information.
git: 'credential-manager-core' is not a git command. See 'git --help'.
bash: line 1: /dev/tty: No such device or address
error: failed to execute prompt script (exit code 1)
fatal: could not read Username for 'https://github.com': No such file or directory
Criando commit...
Traceback (most recent call last):
  File "C:\Users\Eduardo\Documents\cleancrow\python\auto_commit.py", line 37, in <module>
    auto_commit()
    ~~~~~~~~~~~^^
  File "C:\Users\Eduardo\Documents\cleancrow\python\auto_commit.py", line 26, in auto_commit
    subprocess.run(['git', 'push', 'origin', 'main'], check=True)
    ~~~~~~~~~~~~~~^^^^^^^^^^^^^^^^^^^^^^^^^^^^^^^^^^^^^^^^^^^^^^^
  File "C:\Users\Eduardo\AppData\Local\Programs\Python\Python313\Lib\subprocess.py", line 577, in run
    raise CalledProcessError(retcode, process.args,
                             output=stdout, stderr=stderr)
subprocess.CalledProcessError: Command '['git', 'push', 'origin', 'main']' returned non-zero exit status 128.
---------------------------------------- 
----------- 28/04/2025 22:00:01,85 ------------- 
From https://github.com/EduardoDosSantosFerreira/cleancrow
 * branch            main       -> FETCH_HEAD
Already up to date.
warning: in the working copy of 'python/log_autocommit.txt', LF will be replaced by CRLF the next time Git touches it
[main 26d5d66] Atualiza칞칚o autom치tica: 2025-04-28 22:00:04
 1 file changed, 26 insertions(+)
git: 'credential-manager-core' is not a git command. See 'git --help'.
To https://github.com/EduardoDosSantosFerreira/cleancrow
   d8e02af..26d5d66  main -> main
Criando commit...
Commit realizado com sucesso: Atualiza巫o autom磬ica: 2025-04-28 22:00:04
---------------------------------------- 
----------- 29/04/2025 14:30:01,31 ------------- 
From https://github.com/EduardoDosSantosFerreira/cleancrow
 * branch            main       -> FETCH_HEAD
Already up to date.
warning: in the working copy of 'python/log_autocommit.txt', LF will be replaced by CRLF the next time Git touches it
[main 8977325] Atualiza칞칚o autom치tica: 2025-04-29 14:30:03
 1 file changed, 13 insertions(+)
fatal: Unable to persist credentials with the 'wincredman' credential store.
See https://aka.ms/gcm/credstores for more information.
git: 'credential-manager-core' is not a git command. See 'git --help'.
bash: line 1: /dev/tty: No such device or address
error: failed to execute prompt script (exit code 1)
fatal: could not read Username for 'https://github.com': No such file or directory
Criando commit...
Traceback (most recent call last):
  File "C:\Users\Eduardo\Documents\cleancrow\python\auto_commit.py", line 37, in <module>
    auto_commit()
    ~~~~~~~~~~~^^
  File "C:\Users\Eduardo\Documents\cleancrow\python\auto_commit.py", line 26, in auto_commit
    subprocess.run(['git', 'push', 'origin', 'main'], check=True)
    ~~~~~~~~~~~~~~^^^^^^^^^^^^^^^^^^^^^^^^^^^^^^^^^^^^^^^^^^^^^^^
  File "C:\Users\Eduardo\AppData\Local\Programs\Python\Python313\Lib\subprocess.py", line 577, in run
    raise CalledProcessError(retcode, process.args,
                             output=stdout, stderr=stderr)
subprocess.CalledProcessError: Command '['git', 'push', 'origin', 'main']' returned non-zero exit status 128.
---------------------------------------- 
----------- 29/04/2025 17:00:01,61 ------------- 
From https://github.com/EduardoDosSantosFerreira/cleancrow
 * branch            main       -> FETCH_HEAD
Already up to date.
warning: in the working copy of 'python/log_autocommit.txt', LF will be replaced by CRLF the next time Git touches it
[main dbc36fc] Atualiza칞칚o autom치tica: 2025-04-29 17:00:02
 1 file changed, 26 insertions(+)
git: 'credential-manager-core' is not a git command. See 'git --help'.
To https://github.com/EduardoDosSantosFerreira/cleancrow
   26d5d66..dbc36fc  main -> main
Criando commit...
Commit realizado com sucesso: Atualiza巫o autom磬ica: 2025-04-29 17:00:02
---------------------------------------- 
----------- 29/04/2025 22:00:02,19 ------------- 
From https://github.com/EduardoDosSantosFerreira/cleancrow
 * branch            main       -> FETCH_HEAD
Already up to date.
warning: in the working copy of 'python/log_autocommit.txt', LF will be replaced by CRLF the next time Git touches it
[main 4499e24] Atualiza칞칚o autom치tica: 2025-04-29 22:00:06
 1 file changed, 13 insertions(+)
fatal: Unable to persist credentials with the 'wincredman' credential store.
See https://aka.ms/gcm/credstores for more information.
git: 'credential-manager-core' is not a git command. See 'git --help'.
bash: line 1: /dev/tty: No such device or address
error: failed to execute prompt script (exit code 1)
fatal: could not read Username for 'https://github.com': No such file or directory
Criando commit...
Traceback (most recent call last):
  File "C:\Users\Eduardo\Documents\cleancrow\python\auto_commit.py", line 37, in <module>
    auto_commit()
    ~~~~~~~~~~~^^
  File "C:\Users\Eduardo\Documents\cleancrow\python\auto_commit.py", line 26, in auto_commit
    subprocess.run(['git', 'push', 'origin', 'main'], check=True)
    ~~~~~~~~~~~~~~^^^^^^^^^^^^^^^^^^^^^^^^^^^^^^^^^^^^^^^^^^^^^^^
  File "C:\Users\Eduardo\AppData\Local\Programs\Python\Python313\Lib\subprocess.py", line 577, in run
    raise CalledProcessError(retcode, process.args,
                             output=stdout, stderr=stderr)
subprocess.CalledProcessError: Command '['git', 'push', 'origin', 'main']' returned non-zero exit status 128.
---------------------------------------- 
----------- 30/04/2025 14:30:01,56 ------------- 
From https://github.com/EduardoDosSantosFerreira/cleancrow
 * branch            main       -> FETCH_HEAD
Already up to date.
warning: in the working copy of 'python/log_autocommit.txt', LF will be replaced by CRLF the next time Git touches it
[main 983449f] Atualiza칞칚o autom치tica: 2025-04-30 14:30:05
 1 file changed, 26 insertions(+)
git: 'credential-manager-core' is not a git command. See 'git --help'.
To https://github.com/EduardoDosSantosFerreira/cleancrow
   dbc36fc..983449f  main -> main
Criando commit...
Commit realizado com sucesso: Atualiza巫o autom磬ica: 2025-04-30 14:30:05
---------------------------------------- 
----------- 30/04/2025 17:00:02,05 ------------- 
From https://github.com/EduardoDosSantosFerreira/cleancrow
 * branch            main       -> FETCH_HEAD
Already up to date.
warning: in the working copy of 'python/log_autocommit.txt', LF will be replaced by CRLF the next time Git touches it
[main e577e17] Atualiza칞칚o autom치tica: 2025-04-30 17:00:06
 1 file changed, 13 insertions(+)
git: 'credential-manager-core' is not a git command. See 'git --help'.
To https://github.com/EduardoDosSantosFerreira/cleancrow
   983449f..e577e17  main -> main
Criando commit...
Commit realizado com sucesso: Atualiza巫o autom磬ica: 2025-04-30 17:00:06
---------------------------------------- 
----------- 30/04/2025 19:30:01,85 ------------- 
From https://github.com/EduardoDosSantosFerreira/cleancrow
 * branch            main       -> FETCH_HEAD
Already up to date.
warning: in the working copy of 'python/log_autocommit.txt', LF will be replaced by CRLF the next time Git touches it
[main 3000a89] Atualiza칞칚o autom치tica: 2025-04-30 19:30:05
 1 file changed, 13 insertions(+)
git: 'credential-manager-core' is not a git command. See 'git --help'.
To https://github.com/EduardoDosSantosFerreira/cleancrow
   e577e17..3000a89  main -> main
Criando commit...
Commit realizado com sucesso: Atualiza巫o autom磬ica: 2025-04-30 19:30:05
---------------------------------------- 
----------- 30/04/2025 22:00:01,41 ------------- 
From https://github.com/EduardoDosSantosFerreira/cleancrow
 * branch            main       -> FETCH_HEAD
Already up to date.
warning: in the working copy of 'python/log_autocommit.txt', LF will be replaced by CRLF the next time Git touches it
[main 3ab28b0] Atualiza칞칚o autom치tica: 2025-04-30 22:00:05
 1 file changed, 13 insertions(+)
git: 'credential-manager-core' is not a git command. See 'git --help'.
To https://github.com/EduardoDosSantosFerreira/cleancrow
   3000a89..3ab28b0  main -> main
Criando commit...
Commit realizado com sucesso: Atualiza巫o autom磬ica: 2025-04-30 22:00:05
---------------------------------------- 
----------- 01/05/2025 17:00:02,17 ------------- 
